<sdf version="1.5">
   <model name="sicdrone_ardupilot">
      <!-- SIC Drone body -->
      <pose>0 0 0.26 0 0 3.1415927</pose>
      <link name="base_link">
         <pose>0 0 0 0 -0 0</pose>
         <inertial>
            <!-- rear reference point X: -100.044mm, CAD offset: 1001.049mm -->
            <!-- top reference point Z: 33.8663mm, CAD offset: 42.8698mm -->
            <pose>0.001005 0 -0.0090035 0 -0 0</pose>
            <mass>2.02</mass>
            <inertia>
               <ixx>0.011</ixx>
               <ixy>0</ixy>
               <ixz>0</ixz>
               <iyy>0.015</iyy>
               <iyz>0</iyz>
               <izz>0.021</izz>
            </inertia>
         </inertial>
         <collision name="base_link_collision">
            <pose>0 0 0.0 0 0 0</pose>
            <geometry>
               <mesh>
                  <scale>0.001 0.001 0.001</scale>
                  <uri>model://sicdrone_ardupilot/meshes/sic_body.stl</uri>
               </mesh>
               <box>
                  <size>0.67 0.67 0.15</size>
               </box>
            </geometry>
            <surface>
               <contact>
                  <ode>
                     <min_depth>0.001</min_depth>
                     <max_vel>0</max_vel>
                  </ode>
               </contact>
               <friction>
                  <ode />
               </friction>
            </surface>
         </collision>
         <collision name="rear_left_leg_collision">
            <laser_retro>0</laser_retro>
            <max_contacts>10</max_contacts>
            <pose>0.23 -0.153 -0.149 0 -0 0</pose>
            <geometry>
               <cylinder>
                  <radius>0.01</radius>
                  <length>0.14</length>
               </cylinder>
            </geometry>
            <surface>
               <friction>
                  <ode>
                     <mu>1</mu>
                     <mu2>1</mu2>
                     <fdir1>0 0 0</fdir1>
                     <slip1>0</slip1>
                     <slip2>0</slip2>
                  </ode>
                  <torsional>
                     <coefficient>1</coefficient>
                     <patch_radius>0</patch_radius>
                     <surface_radius>0</surface_radius>
                     <use_patch_radius>1</use_patch_radius>
                     <ode>
                        <slip>0</slip>
                     </ode>
                  </torsional>
               </friction>
               <bounce>
                  <restitution_coefficient>0</restitution_coefficient>
                  <threshold>1e+06</threshold>
               </bounce>
               <contact>
                  <collide_without_contact>0</collide_without_contact>
                  <collide_without_contact_bitmask>1</collide_without_contact_bitmask>
                  <collide_bitmask>1</collide_bitmask>
                  <ode>
                     <soft_cfm>0</soft_cfm>
                     <soft_erp>0.2</soft_erp>
                     <kp>1e+13</kp>
                     <kd>1</kd>
                     <max_vel>0.01</max_vel>
                     <min_depth>0</min_depth>
                  </ode>
                  <bullet>
                     <split_impulse>1</split_impulse>
                     <split_impulse_penetration_threshold>-0.01</split_impulse_penetration_threshold>
                     <soft_cfm>0</soft_cfm>
                     <soft_erp>0.2</soft_erp>
                     <kp>1e+13</kp>
                     <kd>1</kd>
                  </bullet>
               </contact>
            </surface>
         </collision>
         <collision name="rear_right_leg_collision">
            <laser_retro>0</laser_retro>
            <max_contacts>10</max_contacts>
            <pose>0.24 0.137 -0.149 0 -0 0</pose>
            <geometry>
               <cylinder>
                  <radius>0.01</radius>
                  <length>0.14</length>
               </cylinder>
            </geometry>
            <surface>
               <friction>
                  <ode>
                     <mu>1</mu>
                     <mu2>1</mu2>
                     <fdir1>0 0 0</fdir1>
                     <slip1>0</slip1>
                     <slip2>0</slip2>
                  </ode>
                  <torsional>
                     <coefficient>1</coefficient>
                     <patch_radius>0</patch_radius>
                     <surface_radius>0</surface_radius>
                     <use_patch_radius>1</use_patch_radius>
                     <ode>
                        <slip>0</slip>
                     </ode>
                  </torsional>
               </friction>
               <bounce>
                  <restitution_coefficient>0</restitution_coefficient>
                  <threshold>1e+06</threshold>
               </bounce>
               <contact>
                  <collide_without_contact>0</collide_without_contact>
                  <collide_without_contact_bitmask>1</collide_without_contact_bitmask>
                  <collide_bitmask>1</collide_bitmask>
                  <ode>
                     <soft_cfm>0</soft_cfm>
                     <soft_erp>0.2</soft_erp>
                     <kp>1e+13</kp>
                     <kd>1</kd>
                     <max_vel>0.01</max_vel>
                     <min_depth>0</min_depth>
                  </ode>
                  <bullet>
                     <split_impulse>1</split_impulse>
                     <split_impulse_penetration_threshold>-0.01</split_impulse_penetration_threshold>
                     <soft_cfm>0</soft_cfm>
                     <soft_erp>0.2</soft_erp>
                     <kp>1e+13</kp>
                     <kd>1</kd>
                  </bullet>
               </contact>
            </surface>
         </collision>
         <collision name="front_left_leg_collision">
            <laser_retro>0</laser_retro>
            <max_contacts>10</max_contacts>
            <pose>-0.26 -0.123 -0.149 0 -0 0</pose>
            <geometry>
               <cylinder>
                  <radius>0.01</radius>
                  <length>0.14</length>
               </cylinder>
            </geometry>
            <surface>
               <friction>
                  <ode>
                     <mu>1</mu>
                     <mu2>1</mu2>
                     <fdir1>0 0 0</fdir1>
                     <slip1>0</slip1>
                     <slip2>0</slip2>
                  </ode>
                  <torsional>
                     <coefficient>1</coefficient>
                     <patch_radius>0</patch_radius>
                     <surface_radius>0</surface_radius>
                     <use_patch_radius>1</use_patch_radius>
                     <ode>
                        <slip>0</slip>
                     </ode>
                  </torsional>
               </friction>
               <bounce>
                  <restitution_coefficient>0</restitution_coefficient>
                  <threshold>1e+06</threshold>
               </bounce>
               <contact>
                  <collide_without_contact>0</collide_without_contact>
                  <collide_without_contact_bitmask>1</collide_without_contact_bitmask>
                  <collide_bitmask>1</collide_bitmask>
                  <ode>
                     <soft_cfm>0</soft_cfm>
                     <soft_erp>0.2</soft_erp>
                     <kp>1e+13</kp>
                     <kd>1</kd>
                     <max_vel>0.01</max_vel>
                     <min_depth>0</min_depth>
                  </ode>
                  <bullet>
                     <split_impulse>1</split_impulse>
                     <split_impulse_penetration_threshold>-0.01</split_impulse_penetration_threshold>
                     <soft_cfm>0</soft_cfm>
                     <soft_erp>0.2</soft_erp>
                     <kp>1e+13</kp>
                     <kd>1</kd>
                  </bullet>
               </contact>
            </surface>
         </collision>
         <collision name="front_right_leg_collision">
            <laser_retro>0</laser_retro>
            <max_contacts>10</max_contacts>
            <pose>-0.245 0.155 -0.149 0 -0 0</pose>
            <geometry>
               <cylinder>
                  <radius>0.01</radius>
                  <length>0.14</length>
               </cylinder>
            </geometry>
            <surface>
               <friction>
                  <ode>
                     <mu>1</mu>
                     <mu2>1</mu2>
                     <fdir1>0 0 0</fdir1>
                     <slip1>0</slip1>
                     <slip2>0</slip2>
                  </ode>
                  <torsional>
                     <coefficient>1</coefficient>
                     <patch_radius>0</patch_radius>
                     <surface_radius>0</surface_radius>
                     <use_patch_radius>1</use_patch_radius>
                     <ode>
                        <slip>0</slip>
                     </ode>
                  </torsional>
               </friction>
               <bounce>
                  <restitution_coefficient>0</restitution_coefficient>
                  <threshold>1e+06</threshold>
               </bounce>
               <contact>
                  <collide_without_contact>0</collide_without_contact>
                  <collide_without_contact_bitmask>1</collide_without_contact_bitmask>
                  <collide_bitmask>1</collide_bitmask>
                  <ode>
                     <soft_cfm>0</soft_cfm>
                     <soft_erp>0.2</soft_erp>
                     <kp>1e+13</kp>
                     <kd>1</kd>
                     <max_vel>0.01</max_vel>
                     <min_depth>0</min_depth>
                  </ode>
                  <bullet>
                     <split_impulse>1</split_impulse>
                     <split_impulse_penetration_threshold>-0.01</split_impulse_penetration_threshold>
                     <soft_cfm>0</soft_cfm>
                     <soft_erp>0.2</soft_erp>
                     <kp>1e+13</kp>
                     <kd>1</kd>
                  </bullet>
               </contact>
            </surface>
         </collision>
         <visual name="base_link_visual">
            <pose>0.36 -0.235 -0.22 1.57 0 3.1</pose>
            <geometry>
               <mesh>
                  <scale>0.001 0.001 0.001</scale>
                  <uri>model://sicdrone_ardupilot/meshes/sic_body.stl</uri>
               </mesh>
            </geometry>
            <material>
               <script>
                  <name>Gazebo/DarkGrey</name>
                  <uri>file://media/materials/scripts/gazebo.material</uri>
               </script>
            </material>
         </visual>
         <gravity>1</gravity>
         <velocity_decay />
         <self_collide>0</self_collide>
      </link>
      <link name="cgo3_mount_link">
         <inertial>
            <!-- place holder -->
            <pose>-0.041 0 -0.162 0 -0 0</pose>
            <mass>0.1</mass>
            <inertia>
               <ixx>0.001</ixx>
               <ixy>0</ixy>
               <ixz>0</ixz>
               <iyy>0.001</iyy>
               <iyz>0</iyz>
               <izz>0.001</izz>
            </inertia>
         </inertial>
         <visual name="cgo3_mount_visual">
            <pose>0 0 0 0 -0 0</pose>
            <geometry>
               <mesh>
                  <scale>0.001 0.001 0.001</scale>
                  <uri>model://sicdrone_ardupilot/meshes/cgo3_mount_remeshed_v1.stl</uri>
               </mesh>
            </geometry>
            <material>
               <script>
                  <name>Gazebo/DarkGrey</name>
                  <uri>file://media/materials/scripts/gazebo.material</uri>
               </script>
            </material>
         </visual>
      </link>
      <joint name="cgo3_mount_joint" type="revolute">
         <child>cgo3_mount_link</child>
         <parent>base_link</parent>
         <pose>0 0 0 0 0 0</pose>
         <axis>
            <xyz>0 0 1</xyz>
            <limit>
               <lower>0</lower>
               <upper>0</upper>
               <effort>100</effort>
               <velocity>-1</velocity>
            </limit>
            <dynamics>
               <damping>1</damping>
            </dynamics>
            <use_parent_model_frame>1</use_parent_model_frame>
         </axis>
         <physics>
            <ode>
               <implicit_spring_damper>1</implicit_spring_damper>
            </ode>
         </physics>
      </joint>
      <link name="cgo3_vertical_arm_link">
         <inertial>
            <!-- place holder -->
            <pose>-0.041 0 -0.162 0 -0 0</pose>
            <mass>0.1</mass>
            <inertia>
               <ixx>0.001</ixx>
               <ixy>0</ixy>
               <ixz>0</ixz>
               <iyy>0.001</iyy>
               <iyz>0</iyz>
               <izz>0.001</izz>
            </inertia>
         </inertial>
         <visual name="cgo3_vertical_arm_visual">
            <pose>0 0 0 0 -0 0</pose>
            <geometry>
               <mesh>
                  <scale>0.001 0.001 0.001</scale>
                  <uri>model://sicdrone_ardupilot/meshes/cgo3_vertical_arm_remeshed_v1.stl</uri>
               </mesh>
            </geometry>
            <material>
               <script>
                  <name>Gazebo/DarkGrey</name>
                  <uri>file://media/materials/scripts/gazebo.material</uri>
               </script>
            </material>
         </visual>
      </link>
      <joint name="cgo3_vertical_arm_joint" type="revolute">
         <child>cgo3_vertical_arm_link</child>
         <parent>cgo3_mount_link</parent>
         <pose>-0.026 0 -0.10 0 0 0</pose>
         <!--
      <controlIndex>6</controlIndex>
      -->
         <axis>
            <xyz>0 0 1</xyz>
            <limit>
               <lower>-1e16</lower>
               <upper>1e16</upper>
               <effort>100</effort>
               <velocity>-1</velocity>
            </limit>
            <dynamics>
               <damping>0.1</damping>
            </dynamics>
            <use_parent_model_frame>1</use_parent_model_frame>
         </axis>
         <physics>
            <ode>
               <implicit_spring_damper>1</implicit_spring_damper>
               <limit>
                  <!-- testing soft limits -->
                  <cfm>0.1</cfm>
                  <erp>0.2</erp>
               </limit>
            </ode>
         </physics>
      </joint>
      <link name="cgo3_horizontal_arm_link">
         <inertial>
            <!-- place holder -->
            <pose>-0.041 0 -0.081 0 -0 0</pose>
            <mass>0.1</mass>
            <inertia>
               <ixx>0.001</ixx>
               <ixy>0</ixy>
               <ixz>0</ixz>
               <iyy>0.001</iyy>
               <iyz>0</iyz>
               <izz>0.001</izz>
            </inertia>
         </inertial>
         <visual name="cgo3_horizontal_arm_visual">
            <pose>0 0 0 0 -0 0</pose>
            <geometry>
               <mesh>
                  <scale>0.001 0.001 0.001</scale>
                  <uri>model://sicdrone_ardupilot/meshes/cgo3_horizontal_arm_remeshed_v1.stl</uri>
               </mesh>
            </geometry>
            <material>
               <script>
                  <name>Gazebo/DarkGrey</name>
                  <uri>file://media/materials/scripts/gazebo.material</uri>
               </script>
            </material>
         </visual>
      </link>
      <joint name="cgo3_horizontal_arm_joint" type="revolute">
         <child>cgo3_horizontal_arm_link</child>
         <parent>cgo3_vertical_arm_link</parent>
         <pose>0.026 0 -0.162 0 0 0</pose>
         <!--
      <controlIndex>7</controlIndex>
      -->
         <axis>
            <xyz>-1 0 0</xyz>
            <limit>
               <lower>-0.785398</lower>
               <upper>0.785398</upper>
               <effort>100</effort>
               <velocity>-1</velocity>
            </limit>
            <dynamics>
               <damping>0.1</damping>
            </dynamics>
            <use_parent_model_frame>1</use_parent_model_frame>
         </axis>
         <physics>
            <ode>
               <implicit_spring_damper>1</implicit_spring_damper>
               <limit>
                  <!-- testing soft limits -->
                  <cfm>0.1</cfm>
                  <erp>0.2</erp>
               </limit>
            </ode>
         </physics>
      </joint>
      <link name="cgo3_camera_link">
         <inertial>
            <!-- place holder -->
            <pose>-0.041 0 -0.162 0 -0 0</pose>
            <mass>0.1</mass>
            <inertia>
               <ixx>0.001</ixx>
               <ixy>0</ixy>
               <ixz>0</ixz>
               <iyy>0.001</iyy>
               <iyz>0</iyz>
               <izz>0.001</izz>
            </inertia>
         </inertial>
         <collision name="cgo3_camera_collision">
            <pose>-0.041 0 -0.162 0 -0 0</pose>
            <geometry>
               <sphere>
                  <radius>0.035</radius>
               </sphere>
            </geometry>
            <surface>
               <friction>
                  <ode>
                     <mu>1</mu>
                     <mu2>1</mu2>
                  </ode>
               </friction>
               <contact>
                  <ode>
                     <kp>1e+8</kp>
                     <kd>1</kd>
                     <max_vel>0.01</max_vel>
                     <min_depth>0.001</min_depth>
                  </ode>
               </contact>
            </surface>
         </collision>
         <visual name="cgo3_camera_visual">
            <pose>0 0 0 0 -0 0</pose>
            <geometry>
               <mesh>
                  <scale>0.001 0.001 0.001</scale>
                  <uri>model://sicdrone_ardupilot/meshes/cgo3_camera_remeshed_v1.stl</uri>
               </mesh>
            </geometry>
            <material>
               <script>
                  <name>Gazebo/DarkGrey</name>
                  <uri>file://media/materials/scripts/gazebo.material</uri>
               </script>
            </material>
         </visual>
         <!-- Sensors -->
         <sensor name="camera_imu" type="imu">
            <always_on>1</always_on>
         </sensor>
         <sensor name="camera" type="camera">
            <pose>-0.051 0 -0.162 0 0 3.14159</pose>
            <camera>
               <horizontal_fov>2.0</horizontal_fov>
               <image>
                  <format>R8G8B8</format>
                  <width>640</width>
                  <height>360</height>
               </image>
               <clip>
                  <near>0.05</near>
                  <far>15000</far>
               </clip>
            </camera>
            <always_on>1</always_on>
            <update_rate>10</update_rate>
            <visualize>false</visualize>
            <!-- how to make this work without using urdf?
        <plugin name="cgo3_camera_controller" filename="libgazebo_ros_camera.so">
          <alwaysOn>true</alwaysOn>
          <updateRate>0.0</updateRate>
          <cameraName>cgo3_camera</cameraName>
          <imageTopicName>image_raw</imageTopicName>
          <cameraInfoTopicName>camera_info</cameraInfoTopicName>
          <frameName>cgo3_camera_optical_frame</frameName>
          <hackBaseline>0.0</hackBaseline>
          <distortionK1>0.0</distortionK1>
          <distortionK2>0.0</distortionK2>
          <distortionK3>0.0</distortionK3>
          <distortionT1>0.0</distortionT1>
          <distortionT2>0.0</distortionT2>
        </plugin>
        -->
            <!-- GStreamer camera plugin (needs a lot of CPU! Consider lowering the
             camera image size when enabling) -->
            <!--
        <plugin name="GstCameraPlugin" filename="libgazebo_gst_camera_plugin.so">
            <robotNamespace></robotNamespace>
            <udpPort>5600</udpPort>
        </plugin>
            <plugin name="GeotaggedImagesPlugin" filename="libgazebo_geotagged_images_plugin.so">
               <robotNamespace>sicdrone</robotNamespace>
               <interval>1</interval>
               <width>3840</width>
               <height>2160</height>
            </plugin>
    -->
         </sensor>
      </link>
      <joint name="cgo3_camera_joint" type="revolute">
         <child>cgo3_camera_link</child>
         <parent>cgo3_horizontal_arm_link</parent>
         <pose>-0.041 0.03 -0.162 0 0 0</pose>
         <axis>
            <xyz>0 -1 0</xyz>
            <limit>
               <lower>-0.0872665</lower>
               <upper>1.5708</upper>
               <effort>100</effort>
               <velocity>-1</velocity>
            </limit>
            <dynamics>
               <damping>0.1</damping>
            </dynamics>
            <use_parent_model_frame>1</use_parent_model_frame>
         </axis>
         <physics>
            <ode>
               <implicit_spring_damper>1</implicit_spring_damper>
               <limit>
                  <!-- testing soft limits -->
                  <cfm>0.1</cfm>
                  <erp>0.2</erp>
               </limit>
            </ode>
         </physics>
      </joint>
      <!-- rotor_left_tilt_arm becomes servo_0 -->
      <link name="servo_0">
         <pose>-0.015 -0.46 0.03 0 -0 0</pose>
         <inertial>
            <pose>0 0.14314 -0.207252 0 -0 0</pose>
            <mass>0.1</mass>
            <inertia>
               <ixx>0.001</ixx>
               <ixy>0</ixy>
               <ixz>0</ixz>
               <iyy>0.001</iyy>
               <iyz>0</iyz>
               <izz>0.001</izz>
            </inertia>
         </inertial>
         <self_collide>0</self_collide>
         <kinematic>0</kinematic>
         <gravity>1</gravity>
         <visual name="servo_0_visual">
            <pose>-0.085 0.37 -0.315 1.57 -0 0</pose>
            <geometry>
               <mesh>
                  <scale>0.001 0.001 0.001</scale>
                  <uri>model://sicdrone_ardupilot/meshes/sic_tilt_arm.stl</uri>
               </mesh>
            </geometry>
            <material>
               <script>
                  <name>Gazebo/DarkGrey</name>
                  <uri>file://media/materials/scripts/gazebo.material</uri>
               </script>
            </material>
         </visual>
      </link>
      <joint name="servo_0_joint" type="revolute">
         <child>servo_0</child>
         <parent>base_link</parent>
         <pose>0.00026 0.040515 -0.103 0 -0 0</pose>
         <axis>
            <xyz>0 1 0</xyz>
            <limit>
               <lower>-1.5708</lower>
               <upper>1.5708</upper>
               <effort>10</effort>
               <velocity>-1</velocity>
            </limit>
            <dynamics>
               <spring_reference>0</spring_reference>
               <spring_stiffness>0</spring_stiffness>
            </dynamics>
            <use_parent_model_frame>1</use_parent_model_frame>
         </axis>
      </joint>
      <!-- rotor_right_tilt_arm becomes servo_1 -->
      <link name="servo_1">
         <pose>0.01 0.47 0.03 0 -0 0</pose>
         <inertial>
            <pose>0 -0.14314 -0.207252 0 -0 0</pose>
            <mass>0.1</mass>
            <inertia>
               <ixx>0.001</ixx>
               <ixy>0</ixy>
               <ixz>0</ixz>
               <iyy>0.001</iyy>
               <iyz>0</iyz>
               <izz>0.001</izz>
            </inertia>
         </inertial>
         <self_collide>0</self_collide>
         <kinematic>0</kinematic>
         <gravity>1</gravity>
         <visual name="servo_1_visual">
            <pose>0.07 -0.37 -0.315 1.57 0 3.1</pose>
            <geometry>
               <mesh>
                  <scale>0.001 0.001 0.001</scale>
                  <uri>model://sicdrone_ardupilot/meshes/sic_tilt_arm.stl</uri>
               </mesh>
            </geometry>
            <material>
               <script>
                  <name>Gazebo/DarkGrey</name>
                  <uri>file://media/materials/scripts/gazebo.material</uri>
               </script>
            </material>
         </visual>
      </link>
      <joint name="servo_1_joint" type="revolute">
         <child>servo_1</child>
         <parent>base_link</parent>
         <pose>0.00026 -0.040515 -0.103 0 -0 3.1415</pose>
         <axis>
            <xyz>0 1 0</xyz>
            <limit>
               <lower>-1.5708</lower>
               <upper>1.5708</upper>
               <effort>10</effort>
               <velocity>-1</velocity>
            </limit>
            <dynamics>
               <spring_reference>0</spring_reference>
               <spring_stiffness>0</spring_stiffness>
            </dynamics>
            <use_parent_model_frame>1</use_parent_model_frame>
         </axis>
      </joint>
      <sensor name="gps_sensor" type="gps">
         <pose>0 0 0 0 0 0</pose>
         <update_rate>10.0</update_rate>
         <always_on>true</always_on>
         <gps>
            <position_sensing>
               <horizontal>
                  <noise type="gaussian_quantized">
                     <mean>0</mean>
                     <stddev>1</stddev>
                     <bias_mean>3</bias_mean>
                     <bias_stddev>1</bias_stddev>
                     <precision>0.5</precision>
                  </noise>
               </horizontal>
               <vertical>
                  <noise type="gaussian_quantized">
                     <mean>0</mean>
                     <stddev>1</stddev>
                     <bias_mean>3</bias_mean>
                     <bias_stddev>1</bias_stddev>
                     <precision>1.0</precision>
                  </noise>
               </vertical>
            </position_sensing>
            <velocity_sensing>
               <horizontal>
                  <noise type="gaussian_quantized">
                     <mean>0</mean>
                     <stddev>0.1</stddev>
                     <bias_mean>0.1</bias_mean>
                     <bias_stddev>0.1</bias_stddev>
                     <precision>0.1</precision>
                  </noise>
               </horizontal>
               <vertical>
                  <noise type="gaussian_quantized">
                     <mean>0</mean>
                     <stddev>0.2</stddev>
                     <bias_mean>0.2</bias_mean>
                     <bias_stddev>0.2</bias_stddev>
                     <precision>0.2</precision>
                  </noise>
               </vertical>
            </velocity_sensing>
         </gps>
      </sensor>
      <link name="imu_link">
         <pose>0 0 0 0 0 3.1415927</pose>
         <inertial>
            <pose>0 0 0 0 -0 0</pose>
            <mass>0.015</mass>
            <inertia>
               <ixx>0.00001</ixx>
               <ixy>0</ixy>
               <ixz>0</ixz>
               <iyy>0.00001</iyy>
               <iyz>0</iyz>
               <izz>0.00001</izz>
            </inertia>
         </inertial>
         <sensor name="imu_sensor" type="imu">
            <pose>0 0 0 3.141593 0 0</pose>
            <always_on>1</always_on>
            <update_rate>1000.0</update_rate>
         </sensor>
      </link>
      <joint name="imu_joint" type="revolute">
         <child>imu_link</child>
         <parent>base_link</parent>
         <axis>
            <xyz>1 0 0</xyz>
            <limit>
               <lower>0</lower>
               <upper>0</upper>
               <effort>0</effort>
               <velocity>0</velocity>
            </limit>
            <dynamics>
               <damping>1.0</damping>
            </dynamics>
            <use_parent_model_frame>1</use_parent_model_frame>
         </axis>
         <physics>
            <ode>
               <implicit_spring_damper>1</implicit_spring_damper>
            </ode>
         </physics>
      </joint>
      <link name="rotor_3">
         <pose>0.334 0.1907 -0.017 0 -0 0</pose>
         <inertial>
            <pose>0 0 0 0 -0 0</pose>
            <mass>0.005</mass>
            <inertia>
               <ixx>9.75e-07</ixx>
               <ixy>0</ixy>
               <ixz>0</ixz>
               <iyy>0.000273104</iyy>
               <iyz>0</iyz>
               <izz>0.000274004</izz>
            </inertia>
         </inertial>
         <collision name="rotor_3_collision">
            <pose>0 0 0 0 -0 0</pose>
            <geometry>
               <cylinder>
                  <length>0.005</length>
                  <radius>0.167</radius>
               </cylinder>
            </geometry>
            <surface>
               <contact>
                  <ode />
               </contact>
               <friction>
                  <ode />
               </friction>
            </surface>
         </collision>
         <visual name="rotor_3_visual">
            <pose>0.128 -0.137762 -0.028 1.57 0 3.1</pose>
            <geometry>
               <mesh>
                  <scale>0.001 0.001 0.001</scale>
                  <uri>model://sicdrone_ardupilot/meshes/sic_prop_generic.stl</uri>
               </mesh>
            </geometry>
            <material>
               <script>
                  <name>Gazebo/Blue</name>
                  <uri>file://media/materials/scripts/gazebo.material</uri>
               </script>
            </material>
         </visual>
         <gravity>1</gravity>
         <velocity_decay />
         <self_collide>0</self_collide>
      </link>
      <joint name="rotor_3_joint" type="revolute">
         <child>rotor_3</child>
         <parent>base_link</parent>
         <axis>
            <xyz>0.0446 -0.0825 1.8977</xyz>
            <limit>
               <lower>-1e+16</lower>
               <upper>1e+16</upper>
               <effort>10</effort>
               <velocity>-1</velocity>
            </limit>
            <dynamics>
               <damping>0.005</damping>
            </dynamics>
            <use_parent_model_frame>1</use_parent_model_frame>
         </axis>
         <physics>
            <ode>
               <implicit_spring_damper>1</implicit_spring_damper>
            </ode>
         </physics>
      </joint>
      <link name="rotor_4">
         <pose>-0.340396 0.212762 -0.017 0 -0 2.0944</pose>
         <inertial>
            <pose>0 0 0 0 -0 0</pose>
            <mass>0.005</mass>
            <inertia>
               <ixx>9.75e-07</ixx>
               <ixy>0</ixy>
               <ixz>0</ixz>
               <iyy>0.000273104</iyy>
               <iyz>0</iyz>
               <izz>0.000274004</izz>
            </inertia>
         </inertial>
         <collision name="rotor_4_collision">
            <pose>0 0 0 0 -0 0</pose>
            <geometry>
               <cylinder>
                  <length>0.005</length>
                  <radius>0.167</radius>
               </cylinder>
            </geometry>
            <surface>
               <contact>
                  <ode />
               </contact>
               <friction>
                  <ode />
               </friction>
            </surface>
         </collision>
         <visual name="rotor_4_visual">
            <pose>0.128 -0.138762 -0.028 1.57 0 3.1</pose>
            <geometry>
               <mesh>
                  <scale>0.001 0.001 0.001</scale>
                  <uri>model://sicdrone_ardupilot/meshes/sic_prop_generic.stl</uri>
               </mesh>
            </geometry>
            <material>
               <script>
                  <name>Gazebo/Blue</name>
                  <uri>file://media/materials/scripts/gazebo.material</uri>
               </script>
            </material>
         </visual>
         <gravity>1</gravity>
         <velocity_decay />
         <self_collide>0</self_collide>
      </link>
      <joint name="rotor_4_joint" type="revolute">
         <child>rotor_4</child>
         <parent>base_link</parent>
         <axis>
            <xyz>0.046 0.0827 1.8977</xyz>
            <limit>
               <lower>-1e+16</lower>
               <upper>1e+16</upper>
               <effort>10</effort>
               <velocity>-1</velocity>
            </limit>
            <dynamics>
               <damping>0.005</damping>
            </dynamics>
            <use_parent_model_frame>1</use_parent_model_frame>
         </axis>
         <physics>
            <ode>
               <implicit_spring_damper>1</implicit_spring_damper>
            </ode>
         </physics>
      </joint>
      <link name="rotor_0">
         <pose>0.011121 0.432705 -0.017 0 -0 0</pose>
         <inertial>
            <pose>0 0 0 0 -0 0</pose>
            <mass>0.005</mass>
            <inertia>
               <ixx>9.75e-07</ixx>
               <ixy>0</ixy>
               <ixz>0</ixz>
               <iyy>0.000273104</iyy>
               <iyz>0</iyz>
               <izz>0.000274004</izz>
            </inertia>
         </inertial>
         <collision name="rotor_0_collision">
            <pose>0 0 0 0 -0 0</pose>
            <geometry>
               <cylinder>
                  <length>0.005</length>
                  <radius>0.137</radius>
               </cylinder>
            </geometry>
            <surface>
               <contact>
                  <ode />
               </contact>
               <friction>
                  <ode />
               </friction>
            </surface>
         </collision>
         <visual name="rotor_0_visual">
            <pose>0.128 -0.139 -0.028 1.57 0 3.1</pose>
            <geometry>
               <mesh>
                  <scale>0.001 0.001 0.001</scale>
                  <uri>model://sicdrone_ardupilot/meshes/sic_prop_generic.stl</uri>
               </mesh>
            </geometry>
            <material>
               <script>
                  <name>Gazebo/DarkGrey</name>
                  <uri>file://media/materials/scripts/gazebo.material</uri>
               </script>
            </material>
         </visual>
         <gravity>1</gravity>
         <velocity_decay />
         <self_collide>0</self_collide>
      </link>
      <joint name="rotor_0_joint" type="revolute">
         <child>rotor_0</child>
         <parent>servo_1</parent>
         <axis>
            <xyz>-0.09563 -0.0003 1.8976</xyz>
            <limit>
               <lower>-1e+16</lower>
               <upper>1e+16</upper>
               <effort>10</effort>
               <velocity>-1</velocity>
            </limit>
            <dynamics>
               <damping>0.005</damping>
            </dynamics>
            <use_parent_model_frame>1</use_parent_model_frame>
         </axis>
         <physics>
            <ode>
               <implicit_spring_damper>1</implicit_spring_damper>
            </ode>
         </physics>
      </joint>
      <link name="rotor_5">
         <pose>0.319 -0.211 -0.017 0 -0 -2.0944</pose>
         <inertial>
            <pose>0 0 0 0 -0 0</pose>
            <mass>0.005</mass>
            <inertia>
               <ixx>9.75e-07</ixx>
               <ixy>0</ixy>
               <ixz>0</ixz>
               <iyy>0.000273104</iyy>
               <iyz>0</iyz>
               <izz>0.000274004</izz>
            </inertia>
         </inertial>
         <collision name="rotor_5_collision">
            <pose>0 0 0 0 -0 0</pose>
            <geometry>
               <cylinder>
                  <length>0.005</length>
                  <radius>0.167</radius>
               </cylinder>
            </geometry>
            <surface>
               <contact>
                  <ode />
               </contact>
               <friction>
                  <ode />
               </friction>
            </surface>
         </collision>
         <visual name="rotor_5_visual">
            <pose>0.125 -0.136705 -0.028 1.57 0 3.1</pose>
            <geometry>
               <mesh>
                  <scale>0.001 0.001 0.001</scale>
                  <uri>model://sicdrone_ardupilot/meshes/sic_prop_generic.stl</uri>
               </mesh>
            </geometry>
            <material>
               <script>
                  <name>Gazebo/DarkGrey</name>
                  <uri>file://media/materials/scripts/gazebo.material</uri>
               </script>
            </material>
         </visual>
         <gravity>1</gravity>
         <velocity_decay />
         <self_collide>0</self_collide>
      </link>
      <joint name="rotor_5_joint" type="revolute">
         <child>rotor_5</child>
         <parent>base_link</parent>
         <axis>
            <xyz>0.0486 0.0811 1.8976</xyz>
            <limit>
               <lower>-1e+16</lower>
               <upper>1e+16</upper>
               <effort>10</effort>
               <velocity>-1</velocity>
            </limit>
            <dynamics>
               <damping>0.005</damping>
            </dynamics>
            <use_parent_model_frame>1</use_parent_model_frame>
         </axis>
         <physics>
            <ode>
               <implicit_spring_damper>1</implicit_spring_damper>
            </ode>
         </physics>
      </joint>
      <link name="rotor_1">
         <pose>-0.018879 -0.418705 -0.017 -0 -0 -2.0944</pose>
         <inertial>
            <pose>0 0 0 0 -0 0</pose>
            <mass>0.005</mass>
            <inertia>
               <ixx>9.75e-07</ixx>
               <ixy>0</ixy>
               <ixz>0</ixz>
               <iyy>0.000273104</iyy>
               <iyz>0</iyz>
               <izz>0.000274004</izz>
            </inertia>
         </inertial>
         <collision name="rotor_1_collision">
            <pose>0 0 0 0 -0 0</pose>
            <geometry>
               <cylinder>
                  <length>0.005</length>
                  <radius>0.137</radius>
               </cylinder>
            </geometry>
            <surface>
               <contact>
                  <ode />
               </contact>
               <friction>
                  <ode />
               </friction>
            </surface>
         </collision>
         <visual name="rotor_1_visual">
            <pose>0.125 -0.135 -0.028 1.57 0 3.1</pose>
            <geometry>
               <mesh>
                  <scale>0.001 0.001 0.001</scale>
                  <uri>model://sicdrone_ardupilot/meshes/sic_prop_generic.stl</uri>
               </mesh>
            </geometry>
            <material>
               <script>
                  <name>Gazebo/Blue</name>
                  <uri>file://media/materials/scripts/gazebo.material</uri>
               </script>
            </material>
         </visual>
         <gravity>1</gravity>
         <velocity_decay />
         <self_collide>0</self_collide>
      </link>
      <joint name="rotor_1_joint" type="revolute">
         <child>rotor_1</child>
         <parent>servo_0</parent>
         <axis>
            <xyz>-0.033996 -0.0006 0.68216</xyz>
            <limit>
               <lower>-1e+16</lower>
               <upper>1e+16</upper>
               <effort>10</effort>
               <velocity>-1</velocity>
            </limit>
            <dynamics>
               <damping>0.005</damping>
            </dynamics>
            <use_parent_model_frame>1</use_parent_model_frame>
         </axis>
         <physics>
            <ode>
               <implicit_spring_damper>1</implicit_spring_damper>
            </ode>
         </physics>
      </joint>
      <link name="rotor_2">
         <pose>-0.355 -0.175 -0.017 0 -0 2.0944</pose>
         <inertial>
            <pose>0 0 0 0 -0 0</pose>
            <mass>0.005</mass>
            <inertia>
               <ixx>9.75e-07</ixx>
               <ixy>0</ixy>
               <ixz>0</ixz>
               <iyy>0.000273104</iyy>
               <iyz>0</iyz>
               <izz>0.000274004</izz>
            </inertia>
         </inertial>
         <collision name="rotor_2_collision">
            <pose>0 0 0 0 -0 0</pose>
            <geometry>
               <cylinder>
                  <length>0.005</length>
                  <radius>0.167</radius>
               </cylinder>
            </geometry>
            <surface>
               <contact>
                  <ode />
               </contact>
               <friction>
                  <ode />
               </friction>
            </surface>
         </collision>
         <visual name="rotor_2_visual">
            <pose>0.127879 -0.132405 -0.028 1.57 0 3.1</pose>
            <geometry>
               <mesh>
                  <scale>0.001 0.001 0.001</scale>
                  <uri>model://sicdrone_ardupilot/meshes/sic_prop_generic.stl</uri>
               </mesh>
            </geometry>
            <material>
               <script>
                  <name>Gazebo/DarkGrey</name>
                  <uri>file://media/materials/scripts/gazebo.material</uri>
               </script>
            </material>
         </visual>
         <gravity>1</gravity>
         <velocity_decay />
         <self_collide>0</self_collide>
      </link>
      <joint name="rotor_2_joint" type="revolute">
         <child>rotor_2</child>
         <parent>base_link</parent>
         <axis>
            <xyz>0.0404 -0.0876 1.8976</xyz>
            <limit>
               <lower>-1e+16</lower>
               <upper>1e+16</upper>
               <effort>10</effort>
               <velocity>-1</velocity>
            </limit>
            <dynamics>
               <damping>0.005</damping>
            </dynamics>
            <use_parent_model_frame>1</use_parent_model_frame>
         </axis>
         <physics>
            <ode>
               <implicit_spring_damper>1</implicit_spring_damper>
            </ode>
         </physics>
      </joint>
      <!-- plugins -->
      <plugin name="rotor_0_blade_1" filename="libLiftDragPlugin.so">
         <a0>0.3</a0>
         <alpha_stall>1.4</alpha_stall>
         <cla>4.500</cla>
         <cda>0.10</cda>
         <cma>0.00</cma>
         <cla_stall>-0.025</cla_stall>
         <cda_stall>0.0</cda_stall>
         <cma_stall>0.0</cma_stall>
         <area>0.002</area>
         <air_density>1.2041</air_density>
         <cp>0.0 0.084 0</cp>
         <forward>1 0 0</forward>
         <upward>0 0 1</upward>
         <link_name>rotor_0</link_name>
      </plugin>
      <plugin name="rotor_0_blade_2" filename="libLiftDragPlugin.so">
         <a0>0.3</a0>
         <alpha_stall>1.4</alpha_stall>
         <cla>4.500</cla>
         <cda>0.10</cda>
         <cma>0.00</cma>
         <cla_stall>-0.025</cla_stall>
         <cda_stall>0.0</cda_stall>
         <cma_stall>0.0</cma_stall>
         <area>0.002</area>
         <air_density>1.2041</air_density>
         <cp>0.0 -0.084 0</cp>
         <forward>-1 0 0</forward>
         <upward>0 0 1</upward>
         <link_name>rotor_0</link_name>
      </plugin>
      <plugin name="rotor_0_blade_3" filename="libLiftDragPlugin.so">
         <a0>0.3</a0>
         <alpha_stall>1.4</alpha_stall>
         <cla>4.500</cla>
         <cda>0.10</cda>
         <cma>0.00</cma>
         <cla_stall>-0.025</cla_stall>
         <cda_stall>0.0</cda_stall>
         <cma_stall>0.0</cma_stall>
         <area>0.002</area>
         <air_density>1.2041</air_density>
         <cp>0.0 0.084 0</cp>
         <forward>1 0 0</forward>
         <upward>0 0 1</upward>
         <link_name>rotor_0</link_name>
      </plugin>
      <plugin name="rotor_1_blade_1" filename="libLiftDragPlugin.so">
         <a0>0.3</a0>
         <alpha_stall>1.4</alpha_stall>
         <cla>4.500</cla>
         <cda>0.10</cda>
         <cma>0.00</cma>
         <cla_stall>-0.025</cla_stall>
         <cda_stall>0.0</cda_stall>
         <cma_stall>0.0</cma_stall>
         <area>0.002</area>
         <air_density>1.2041</air_density>
         <cp>0.0 0.084 0</cp>
         <forward>-1 0 0</forward>
         <upward>0 0 1</upward>
         <link_name>rotor_1</link_name>
      </plugin>
      <plugin name="rotor_1_blade_2" filename="libLiftDragPlugin.so">
         <a0>0.3</a0>
         <alpha_stall>1.4</alpha_stall>
         <cla>4.500</cla>
         <cda>0.10</cda>
         <cma>0.00</cma>
         <cla_stall>-0.025</cla_stall>
         <cda_stall>0.0</cda_stall>
         <cma_stall>0.0</cma_stall>
         <area>0.002</area>
         <air_density>1.2041</air_density>
         <cp>0.0 -0.084 0</cp>
         <forward>1 0 0</forward>
         <upward>0 0 1</upward>
         <link_name>rotor_1</link_name>
      </plugin>
      <plugin name="rotor_1_blade_3" filename="libLiftDragPlugin.so">
         <a0>0.3</a0>
         <alpha_stall>1.4</alpha_stall>
         <cla>4.500</cla>
         <cda>0.10</cda>
         <cma>0.00</cma>
         <cla_stall>-0.025</cla_stall>
         <cda_stall>0.0</cda_stall>
         <cma_stall>0.0</cma_stall>
         <area>0.002</area>
         <air_density>1.2041</air_density>
         <cp>0.0 0.084 0</cp>
         <forward>-1 0 0</forward>
         <upward>0 0 1</upward>
         <link_name>rotor_1</link_name>
      </plugin>
      <plugin name="rotor_2_blade_1" filename="libLiftDragPlugin.so">
         <a0>0.3</a0>
         <alpha_stall>1.4</alpha_stall>
         <cla>4.500</cla>
         <cda>0.10</cda>
         <cma>0.00</cma>
         <cla_stall>-0.025</cla_stall>
         <cda_stall>0.0</cda_stall>
         <cma_stall>0.0</cma_stall>
         <area>0.002</area>
         <air_density>1.2041</air_density>
         <cp>0.0 0.084 0</cp>
         <forward>1 0 0</forward>
         <upward>0 0 1</upward>
         <link_name>rotor_2</link_name>
      </plugin>
      <plugin name="rotor_2_blade_2" filename="libLiftDragPlugin.so">
         <a0>0.3</a0>
         <alpha_stall>1.4</alpha_stall>
         <cla>4.500</cla>
         <cda>0.10</cda>
         <cma>0.00</cma>
         <cla_stall>-0.025</cla_stall>
         <cda_stall>0.0</cda_stall>
         <cma_stall>0.0</cma_stall>
         <area>0.002</area>
         <air_density>1.2041</air_density>
         <cp>0.0 -0.084 0</cp>
         <forward>-1 0 0</forward>
         <upward>0 0 1</upward>
         <link_name>rotor_2</link_name>
      </plugin>
      <plugin name="rotor_2_blade_3" filename="libLiftDragPlugin.so">
         <a0>0.3</a0>
         <alpha_stall>1.4</alpha_stall>
         <cla>4.500</cla>
         <cda>0.10</cda>
         <cma>0.00</cma>
         <cla_stall>-0.025</cla_stall>
         <cda_stall>0.0</cda_stall>
         <cma_stall>0.0</cma_stall>
         <area>0.002</area>
         <air_density>1.2041</air_density>
         <cp>0.0 0.084 0</cp>
         <forward>1 0 0</forward>
         <upward>0 0 1</upward>
         <link_name>rotor_2</link_name>
      </plugin>
      <plugin name="rotor_3_blade_1" filename="libLiftDragPlugin.so">
         <a0>0.3</a0>
         <alpha_stall>1.4</alpha_stall>
         <cla>4.500</cla>
         <cda>0.10</cda>
         <cma>0.00</cma>
         <cla_stall>-0.025</cla_stall>
         <cda_stall>0.0</cda_stall>
         <cma_stall>0.0</cma_stall>
         <area>0.002</area>
         <air_density>1.2041</air_density>
         <cp>0.0 0.084 0</cp>
         <forward>-1 0 0</forward>
         <upward>0 0 1</upward>
         <link_name>rotor_3</link_name>
      </plugin>
      <plugin name="rotor_3_blade_2" filename="libLiftDragPlugin.so">
         <a0>0.3</a0>
         <alpha_stall>1.4</alpha_stall>
         <cla>4.500</cla>
         <cda>0.10</cda>
         <cma>0.00</cma>
         <cla_stall>-0.025</cla_stall>
         <cda_stall>0.0</cda_stall>
         <cma_stall>0.0</cma_stall>
         <area>0.002</area>
         <air_density>1.2041</air_density>
         <cp>0.0 -0.084 0</cp>
         <forward>1 0 0</forward>
         <upward>0 0 1</upward>
         <link_name>rotor_3</link_name>
      </plugin>
      <plugin name="rotor_3_blade_3" filename="libLiftDragPlugin.so">
         <a0>0.3</a0>
         <alpha_stall>1.4</alpha_stall>
         <cla>4.500</cla>
         <cda>0.10</cda>
         <cma>0.00</cma>
         <cla_stall>-0.025</cla_stall>
         <cda_stall>0.0</cda_stall>
         <cma_stall>0.0</cma_stall>
         <area>0.002</area>
         <air_density>1.2041</air_density>
         <cp>0.0 0.084 0</cp>
         <forward>-1 0 0</forward>
         <upward>0 0 1</upward>
         <link_name>rotor_3</link_name>
      </plugin>
      <plugin name="rotor_4_blade_1" filename="libLiftDragPlugin.so">
         <a0>0.3</a0>
         <alpha_stall>1.4</alpha_stall>
         <cla>4.500</cla>
         <cda>0.10</cda>
         <cma>0.00</cma>
         <cla_stall>-0.025</cla_stall>
         <cda_stall>0.0</cda_stall>
         <cma_stall>0.0</cma_stall>
         <area>0.002</area>
         <air_density>1.2041</air_density>
         <cp>0.0 0.084 0</cp>
         <forward>-1 0 0</forward>
         <upward>0 0 1</upward>
         <link_name>rotor_4</link_name>
      </plugin>
      <plugin name="rotor_4_blade_2" filename="libLiftDragPlugin.so">
         <a0>0.3</a0>
         <alpha_stall>1.4</alpha_stall>
         <cla>4.500</cla>
         <cda>0.10</cda>
         <cma>0.00</cma>
         <cla_stall>-0.025</cla_stall>
         <cda_stall>0.0</cda_stall>
         <cma_stall>0.0</cma_stall>
         <area>0.002</area>
         <air_density>1.2041</air_density>
         <cp>0.0 -0.084 0</cp>
         <forward>1 0 0</forward>
         <upward>0 0 1</upward>
         <link_name>rotor_4</link_name>
      </plugin>
      <plugin name="rotor_4_blade_3" filename="libLiftDragPlugin.so">
         <a0>0.3</a0>
         <alpha_stall>1.4</alpha_stall>
         <cla>4.500</cla>
         <cda>0.10</cda>
         <cma>0.00</cma>
         <cla_stall>-0.025</cla_stall>
         <cda_stall>0.0</cda_stall>
         <cma_stall>0.0</cma_stall>
         <area>0.002</area>
         <air_density>1.2041</air_density>
         <cp>0.0 0.084 0</cp>
         <forward>-1 0 0</forward>
         <upward>0 0 1</upward>
         <link_name>rotor_4</link_name>
      </plugin>
      <plugin name="rotor_5_blade_1" filename="libLiftDragPlugin.so">
         <a0>0.3</a0>
         <alpha_stall>1.4</alpha_stall>
         <cla>4.500</cla>
         <cda>0.10</cda>
         <cma>0.00</cma>
         <cla_stall>-0.025</cla_stall>
         <cda_stall>0.0</cda_stall>
         <cma_stall>0.0</cma_stall>
         <area>0.002</area>
         <air_density>1.2041</air_density>
         <cp>0.0 0.084 0</cp>
         <forward>1 0 0</forward>
         <upward>0 0 1</upward>
         <link_name>rotor_5</link_name>
      </plugin>
      <plugin name="rotor_5_blade_2" filename="libLiftDragPlugin.so">
         <a0>0.3</a0>
         <alpha_stall>1.4</alpha_stall>
         <cla>4.500</cla>
         <cda>0.10</cda>
         <cma>0.00</cma>
         <cla_stall>-0.025</cla_stall>
         <cda_stall>0.0</cda_stall>
         <cma_stall>0.0</cma_stall>
         <area>0.002</area>
         <air_density>1.2041</air_density>
         <cp>0.0 -0.084 0</cp>
         <forward>-1 0 0</forward>
         <upward>0 0 1</upward>
         <link_name>rotor_5</link_name>
      </plugin>
      <plugin name="rotor_5_blade_3" filename="libLiftDragPlugin.so">
         <a0>0.3</a0>
         <alpha_stall>1.4</alpha_stall>
         <cla>4.500</cla>
         <cda>0.10</cda>
         <cma>0.00</cma>
         <cla_stall>-0.025</cla_stall>
         <cda_stall>0.0</cda_stall>
         <cma_stall>0.0</cma_stall>
         <area>0.002</area>
         <air_density>1.2041</air_density>
         <cp>0.0 0.084 0</cp>
         <forward>1 0 0</forward>
         <upward>0 0 1</upward>
         <link_name>rotor_5</link_name>
      </plugin>
      <plugin name="ardupilot_plugin" filename="libArduPilotPlugin.so">
         <fdm_addr>127.0.0.1</fdm_addr>
         <fdm_port_in>9002</fdm_port_in>
         <fdm_port_out>9003</fdm_port_out>
         <modelXYZToAirplaneXForwardZDown>0 0 0 3.141593 0 3.141593</modelXYZToAirplaneXForwardZDown>
         <gazeboXYZToNED>0 0 0 3.141593 0 3.141593</gazeboXYZToNED>
         <imuName>sicdrone_ardupilot::imu_link::imu_sensor</imuName>
         <connectionTimeoutMaxCount>5</connectionTimeoutMaxCount>
         <!--
          incoming control command [0, 1]
          so offset it by 0 to get [0, 1]
          and divide max target by 1.
          offset = 0
          multiplier = 838 max rpm / 1 = 838
        -->
         <control channel="0">
            <type>VELOCITY</type>
            <offset>0</offset>
            <p_gain>0.20</p_gain>
            <i_gain>0</i_gain>
            <d_gain>0</d_gain>
            <i_max>0</i_max>
            <i_min>0</i_min>
            <cmd_max>2.5</cmd_max>
            <cmd_min>-2.5</cmd_min>
            <jointName>rotor_0_joint</jointName>
            <multiplier>-1200</multiplier>
            <controlVelocitySlowdownSim>1</controlVelocitySlowdownSim>
         </control>
         <control channel="1">
            <type>VELOCITY</type>
            <offset>0</offset>
            <p_gain>0.20</p_gain>
            <i_gain>0</i_gain>
            <d_gain>0</d_gain>
            <i_max>0</i_max>
            <i_min>0</i_min>
            <cmd_max>2.5</cmd_max>
            <cmd_min>-2.5</cmd_min>
            <jointName>rotor_1_joint</jointName>
            <multiplier>1200</multiplier>
            <controlVelocitySlowdownSim>1</controlVelocitySlowdownSim>
         </control>
         <control channel="2">
            <type>VELOCITY</type>
            <offset>0</offset>
            <p_gain>0.20</p_gain>
            <i_gain>0</i_gain>
            <d_gain>0</d_gain>
            <i_max>0</i_max>
            <i_min>0</i_min>
            <cmd_max>2.5</cmd_max>
            <cmd_min>-2.5</cmd_min>
            <jointName>rotor_2_joint</jointName>
            <multiplier>-1200</multiplier>
            <controlVelocitySlowdownSim>1</controlVelocitySlowdownSim>
         </control>
         <control channel="3">
            <type>VELOCITY</type>
            <offset>0</offset>
            <p_gain>0.20</p_gain>
            <i_gain>0</i_gain>
            <d_gain>0</d_gain>
            <i_max>0</i_max>
            <i_min>0</i_min>
            <cmd_max>2.5</cmd_max>
            <cmd_min>-2.5</cmd_min>
            <jointName>rotor_3_joint</jointName>
            <multiplier>1200</multiplier>
            <controlVelocitySlowdownSim>1</controlVelocitySlowdownSim>
         </control>
         <control channel="4">
            <type>VELOCITY</type>
            <offset>0</offset>
            <p_gain>0.20</p_gain>
            <i_gain>0</i_gain>
            <d_gain>0</d_gain>
            <i_max>0</i_max>
            <i_min>0</i_min>
            <cmd_max>2.5</cmd_max>
            <cmd_min>-2.5</cmd_min>
            <jointName>rotor_4_joint</jointName>
            <multiplier>1200</multiplier>
            <controlVelocitySlowdownSim>1</controlVelocitySlowdownSim>
         </control>
         <control channel="5">
            <type>VELOCITY</type>
            <offset>0</offset>
            <p_gain>0.20</p_gain>
            <i_gain>0</i_gain>
            <d_gain>0</d_gain>
            <i_max>0</i_max>
            <i_min>0</i_min>
            <cmd_max>2.5</cmd_max>
            <cmd_min>-2.5</cmd_min>
            <jointName>rotor_5_joint</jointName>
            <multiplier>-1200</multiplier>
            <controlVelocitySlowdownSim>1</controlVelocitySlowdownSim>
         </control>
         <!-- servo 0 is for the left tiltrotor -->
         <control channel="6">
            <type>POSITION</type>
            <offset>0</offset>
            <p_gain>100</p_gain>
            <i_gain>0</i_gain>
            <d_gain>0</d_gain>
            <i_max>0</i_max>
            <i_min>0</i_min>
            <cmd_max>2</cmd_max>
            <cmd_min>-2</cmd_min>
            <jointName>servo_0_joint</jointName>
            <multiplier>1.5</multiplier>
            <controlVelocitySlowdownSim>1</controlVelocitySlowdownSim>
            <joint_name>servo_0_joint</joint_name>
            <!-- servo 1 is for the left tiltrotor -->
         </control>
         <control channel="7">
            <type>POSITION</type>
            <offset>0</offset>
            <p_gain>100</p_gain>
            <i_gain>0</i_gain>
            <d_gain>0</d_gain>
            <i_max>0</i_max>
            <i_min>0</i_min>
            <cmd_max>2</cmd_max>
            <cmd_min>-2</cmd_min>
            <jointName>servo_1_joint</jointName>
            <multiplier>-1.5</multiplier>
            <controlVelocitySlowdownSim>1</controlVelocitySlowdownSim>
         </control>
      </plugin>
      <static>0</static>
   </model>
</sdf>

